INFO:django.utils.autoreload:/Users/aksharasadheesh/Desktop/tigerlab/api/views.py changed, reloading.
INFO:root:Success no key error
DEBUG:root:NoneType: None

DEBUG:root:Traceback (most recent call last):
  File "/Users/aksharasadheesh/Desktop/tigerlab/api/views.py", line 38, in uploadfile
    objs = [
  File "/Users/aksharasadheesh/Desktop/tigerlab/api/views.py", line 42, in <listcomp>
    team_name_1 = row["team_1 name"],
KeyError: 'team_1 name'

INFO:root:Success key fall back
DEBUG:root:NoneType: None

DEBUG:root:Traceback (most recent call last):
  File "/Users/aksharasadheesh/Desktop/tigerlab/api/views.py", line 38, in uploadfile
    objs = [
  File "/Users/aksharasadheesh/Desktop/tigerlab/api/views.py", line 42, in <listcomp>
    team_name_1 = row["team_1 name"],
KeyError: 'team_1 name'

INFO:root:Success key fall back
DEBUG:root:Traceback (most recent call last):
  File "/Users/aksharasadheesh/Desktop/tigerlab/api/views.py", line 38, in uploadfile
    objs = [
  File "/Users/aksharasadheesh/Desktop/tigerlab/api/views.py", line 42, in <listcomp>
    team_name_1 = row["team_1 name"],
KeyError: 'team_1 name'

During handling of the above exception, another exception occurred:

Traceback (most recent call last):
  File "/Users/aksharasadheesh/Desktop/tigerlab/api/views.py", line 63, in uploadfile
    d = {"team_1 name" : l[0], "team_1 score" : l[1], "team_2 name" : l[2],"team_2 score" : l[3]}
IndexError: list index out of range

DEBUG:root:Traceback (most recent call last):
  File "/Users/aksharasadheesh/Desktop/tigerlab/api/views.py", line 38, in uploadfile
    objs = [
  File "/Users/aksharasadheesh/Desktop/tigerlab/api/views.py", line 42, in <listcomp>
    team_name_1 = row["team_1 name"],
KeyError: 'team_1 name'

INFO:root:Success key fall back
DEBUG:root:Traceback (most recent call last):
  File "/Users/aksharasadheesh/Desktop/tigerlab/api/views.py", line 38, in uploadfile
    objs = [
  File "/Users/aksharasadheesh/Desktop/tigerlab/api/views.py", line 42, in <listcomp>
    team_name_1 = row["team_1 name"],
KeyError: 'team_1 name'

During handling of the above exception, another exception occurred:

Traceback (most recent call last):
  File "/Users/aksharasadheesh/Desktop/tigerlab/api/views.py", line 63, in uploadfile
    d = {"team_1 name" : l[0], "team_1 score" : l[1], "team_2 name" : l[2],"team_2 score" : l[3]}
IndexError: list index out of range

DEBUG:root:Traceback (most recent call last):
  File "/Users/aksharasadheesh/Desktop/tigerlab/api/views.py", line 38, in uploadfile
    objs = [
  File "/Users/aksharasadheesh/Desktop/tigerlab/api/views.py", line 42, in <listcomp>
    team_name_1 = row["team_1 name"],
KeyError: 'team_1 name'

INFO:root:Success key fall back
DEBUG:root:Traceback (most recent call last):
  File "/Users/aksharasadheesh/Desktop/tigerlab/api/views.py", line 38, in uploadfile
    objs = [
  File "/Users/aksharasadheesh/Desktop/tigerlab/api/views.py", line 42, in <listcomp>
    team_name_1 = row["team_1 name"],
KeyError: 'team_1 name'

During handling of the above exception, another exception occurred:

Traceback (most recent call last):
  File "/Users/aksharasadheesh/Desktop/tigerlab/api/views.py", line 63, in uploadfile
    d = {"team_1 name" : l[0], "team_1 score" : l[1], "team_2 name" : l[2],"team_2 score" : l[3]}
IndexError: list index out of range

INFO:root:Success no key error
DEBUG:root:NoneType: None

INFO:root:Success no key error
DEBUG:root:NoneType: None

DEBUG:root:Traceback (most recent call last):
  File "/Users/aksharasadheesh/Desktop/tigerlab/api/views.py", line 38, in uploadfile
    objs = [
  File "/Users/aksharasadheesh/Desktop/tigerlab/api/views.py", line 42, in <listcomp>
    team_name_1 = row["team_1 name"],
KeyError: 'team_1 name'

INFO:root:Success key fall back
DEBUG:root:NoneType: None

INFO:django.utils.autoreload:/Users/aksharasadheesh/Desktop/tigerlab/api/views.py changed, reloading.
DEBUG:root:Traceback (most recent call last):
  File "/Users/aksharasadheesh/Desktop/tigerlab/api/views.py", line 38, in uploadfile
    objs = [
  File "/Users/aksharasadheesh/Desktop/tigerlab/api/views.py", line 42, in <listcomp>
    team_name_1 = row["team_1 name"],
KeyError: 'team_1 name'

INFO:root:Success key fall back
DEBUG:root:Traceback (most recent call last):
  File "/Users/aksharasadheesh/Desktop/tigerlab/api/views.py", line 38, in uploadfile
    objs = [
  File "/Users/aksharasadheesh/Desktop/tigerlab/api/views.py", line 42, in <listcomp>
    team_name_1 = row["team_1 name"],
KeyError: 'team_1 name'

INFO:root:Success key fall back
ERROR:django.request:Internal Server Error: /ranks/uploadfile/
Traceback (most recent call last):
  File "/Users/aksharasadheesh/Desktop/tigerlab/api/views.py", line 38, in uploadfile
    objs = [
  File "/Users/aksharasadheesh/Desktop/tigerlab/api/views.py", line 42, in <listcomp>
    team_name_1 = row["team_1 name"],
KeyError: 'team_1 name'

During handling of the above exception, another exception occurred:

Traceback (most recent call last):
  File "/Users/aksharasadheesh/Desktop/tigerlab/venv/lib/python3.10/site-packages/django/core/handlers/exception.py", line 56, in inner
    response = get_response(request)
  File "/Users/aksharasadheesh/Desktop/tigerlab/venv/lib/python3.10/site-packages/django/core/handlers/base.py", line 197, in _get_response
    response = wrapped_callback(request, *callback_args, **callback_kwargs)
  File "/Users/aksharasadheesh/Desktop/tigerlab/venv/lib/python3.10/site-packages/django/views/decorators/csrf.py", line 55, in wrapped_view
    return view_func(*args, **kwargs)
  File "/Users/aksharasadheesh/Desktop/tigerlab/venv/lib/python3.10/site-packages/rest_framework/viewsets.py", line 125, in view
    return self.dispatch(request, *args, **kwargs)
  File "/Users/aksharasadheesh/Desktop/tigerlab/venv/lib/python3.10/site-packages/rest_framework/views.py", line 509, in dispatch
    response = self.handle_exception(exc)
  File "/Users/aksharasadheesh/Desktop/tigerlab/venv/lib/python3.10/site-packages/rest_framework/views.py", line 469, in handle_exception
    self.raise_uncaught_exception(exc)
  File "/Users/aksharasadheesh/Desktop/tigerlab/venv/lib/python3.10/site-packages/rest_framework/views.py", line 480, in raise_uncaught_exception
    raise exc
  File "/Users/aksharasadheesh/Desktop/tigerlab/venv/lib/python3.10/site-packages/rest_framework/views.py", line 506, in dispatch
    response = handler(request, *args, **kwargs)
  File "/Users/aksharasadheesh/Desktop/tigerlab/api/views.py", line 63, in uploadfile
    d = {"team_1 name" : l[0], "team_1 score" : l[1], "team_2 name" : l[2],"team_2 score" : l[3]}
IndexError: list index out of range
INFO:django.utils.autoreload:/Users/aksharasadheesh/Desktop/tigerlab/api/views.py changed, reloading.
DEBUG:root:Traceback (most recent call last):
  File "/Users/aksharasadheesh/Desktop/tigerlab/api/views.py", line 38, in uploadfile
    objs = [
  File "/Users/aksharasadheesh/Desktop/tigerlab/api/views.py", line 42, in <listcomp>
    team_name_1 = row["team_1 name"],
KeyError: 'team_1 name'

INFO:root:Success key fall back
ERROR:django.request:Internal Server Error: /ranks/uploadfile/
Traceback (most recent call last):
  File "/Users/aksharasadheesh/Desktop/tigerlab/api/views.py", line 38, in uploadfile
    objs = [
  File "/Users/aksharasadheesh/Desktop/tigerlab/api/views.py", line 42, in <listcomp>
    team_name_1 = row["team_1 name"],
KeyError: 'team_1 name'

During handling of the above exception, another exception occurred:

Traceback (most recent call last):
  File "/Users/aksharasadheesh/Desktop/tigerlab/venv/lib/python3.10/site-packages/django/core/handlers/exception.py", line 56, in inner
    response = get_response(request)
  File "/Users/aksharasadheesh/Desktop/tigerlab/venv/lib/python3.10/site-packages/django/core/handlers/base.py", line 197, in _get_response
    response = wrapped_callback(request, *callback_args, **callback_kwargs)
  File "/Users/aksharasadheesh/Desktop/tigerlab/venv/lib/python3.10/site-packages/django/views/decorators/csrf.py", line 55, in wrapped_view
    return view_func(*args, **kwargs)
  File "/Users/aksharasadheesh/Desktop/tigerlab/venv/lib/python3.10/site-packages/rest_framework/viewsets.py", line 125, in view
    return self.dispatch(request, *args, **kwargs)
  File "/Users/aksharasadheesh/Desktop/tigerlab/venv/lib/python3.10/site-packages/rest_framework/views.py", line 509, in dispatch
    response = self.handle_exception(exc)
  File "/Users/aksharasadheesh/Desktop/tigerlab/venv/lib/python3.10/site-packages/rest_framework/views.py", line 469, in handle_exception
    self.raise_uncaught_exception(exc)
  File "/Users/aksharasadheesh/Desktop/tigerlab/venv/lib/python3.10/site-packages/rest_framework/views.py", line 480, in raise_uncaught_exception
    raise exc
  File "/Users/aksharasadheesh/Desktop/tigerlab/venv/lib/python3.10/site-packages/rest_framework/views.py", line 506, in dispatch
    response = handler(request, *args, **kwargs)
  File "/Users/aksharasadheesh/Desktop/tigerlab/api/views.py", line 64, in uploadfile
    d = {"team_1 name" : l[0], "team_1 score" : l[1], "team_2 name" : l[2],"team_2 score" : l[3]}
IndexError: list index out of range
INFO:django.utils.autoreload:/Users/aksharasadheesh/Desktop/tigerlab/api/views.py changed, reloading.
DEBUG:root:Traceback (most recent call last):
  File "/Users/aksharasadheesh/Desktop/tigerlab/api/views.py", line 38, in uploadfile
    objs = [
  File "/Users/aksharasadheesh/Desktop/tigerlab/api/views.py", line 42, in <listcomp>
    team_name_1 = row["team_1 name"],
KeyError: 'team_1 name'

INFO:root:Success key fall back
ERROR:django.request:Internal Server Error: /ranks/uploadfile/
Traceback (most recent call last):
  File "/Users/aksharasadheesh/Desktop/tigerlab/api/views.py", line 38, in uploadfile
    objs = [
  File "/Users/aksharasadheesh/Desktop/tigerlab/api/views.py", line 42, in <listcomp>
    team_name_1 = row["team_1 name"],
KeyError: 'team_1 name'

During handling of the above exception, another exception occurred:

Traceback (most recent call last):
  File "/Users/aksharasadheesh/Desktop/tigerlab/venv/lib/python3.10/site-packages/django/core/handlers/exception.py", line 56, in inner
    response = get_response(request)
  File "/Users/aksharasadheesh/Desktop/tigerlab/venv/lib/python3.10/site-packages/django/core/handlers/base.py", line 197, in _get_response
    response = wrapped_callback(request, *callback_args, **callback_kwargs)
  File "/Users/aksharasadheesh/Desktop/tigerlab/venv/lib/python3.10/site-packages/django/views/decorators/csrf.py", line 55, in wrapped_view
    return view_func(*args, **kwargs)
  File "/Users/aksharasadheesh/Desktop/tigerlab/venv/lib/python3.10/site-packages/rest_framework/viewsets.py", line 125, in view
    return self.dispatch(request, *args, **kwargs)
  File "/Users/aksharasadheesh/Desktop/tigerlab/venv/lib/python3.10/site-packages/rest_framework/views.py", line 509, in dispatch
    response = self.handle_exception(exc)
  File "/Users/aksharasadheesh/Desktop/tigerlab/venv/lib/python3.10/site-packages/rest_framework/views.py", line 469, in handle_exception
    self.raise_uncaught_exception(exc)
  File "/Users/aksharasadheesh/Desktop/tigerlab/venv/lib/python3.10/site-packages/rest_framework/views.py", line 480, in raise_uncaught_exception
    raise exc
  File "/Users/aksharasadheesh/Desktop/tigerlab/venv/lib/python3.10/site-packages/rest_framework/views.py", line 506, in dispatch
    response = handler(request, *args, **kwargs)
  File "/Users/aksharasadheesh/Desktop/tigerlab/api/views.py", line 63, in uploadfile
    d = {"team_1 name" : l[0], "team_1 score" : l[1], "team_2 name" : l[2],"team_2 score" : l[3]}
IndexError: list index out of range
INFO:django.utils.autoreload:/Users/aksharasadheesh/Desktop/tigerlab/api/views.py changed, reloading.
DEBUG:root:Traceback (most recent call last):
  File "/Users/aksharasadheesh/Desktop/tigerlab/api/views.py", line 38, in uploadfile
    objs = [
  File "/Users/aksharasadheesh/Desktop/tigerlab/api/views.py", line 42, in <listcomp>
    team_name_1 = row["team_1 name"],
KeyError: 'team_1 name'

INFO:root:Success key fall back
INFO:django.utils.autoreload:/Users/aksharasadheesh/Desktop/tigerlab/api/views.py changed, reloading.
WARNING:django.request:Method Not Allowed: /ranks/uploadfile/
DEBUG:root:Traceback (most recent call last):
  File "/Users/aksharasadheesh/Desktop/tigerlab/api/views.py", line 38, in uploadfile
    objs = [
  File "/Users/aksharasadheesh/Desktop/tigerlab/api/views.py", line 42, in <listcomp>
    team_name_1 = row["team_1 name"],
KeyError: 'team_1 name'

INFO:root:Success key fall back
INFO:django.utils.autoreload:/Users/aksharasadheesh/Desktop/tigerlab/api/views.py changed, reloading.
DEBUG:root:Traceback (most recent call last):
  File "/Users/aksharasadheesh/Desktop/tigerlab/api/views.py", line 38, in uploadfile
    objs = [
  File "/Users/aksharasadheesh/Desktop/tigerlab/api/views.py", line 42, in <listcomp>
    team_name_1 = row["team_1 name"],
KeyError: 'team_1 name'

INFO:root:Success key fall back
ERROR:django.request:Internal Server Error: /ranks/uploadfile/
Traceback (most recent call last):
  File "/Users/aksharasadheesh/Desktop/tigerlab/api/views.py", line 38, in uploadfile
    objs = [
  File "/Users/aksharasadheesh/Desktop/tigerlab/api/views.py", line 42, in <listcomp>
    team_name_1 = row["team_1 name"],
KeyError: 'team_1 name'

During handling of the above exception, another exception occurred:

Traceback (most recent call last):
  File "/Users/aksharasadheesh/Desktop/tigerlab/venv/lib/python3.10/site-packages/django/core/handlers/exception.py", line 56, in inner
    response = get_response(request)
  File "/Users/aksharasadheesh/Desktop/tigerlab/venv/lib/python3.10/site-packages/django/core/handlers/base.py", line 197, in _get_response
    response = wrapped_callback(request, *callback_args, **callback_kwargs)
  File "/Users/aksharasadheesh/Desktop/tigerlab/venv/lib/python3.10/site-packages/django/views/decorators/csrf.py", line 55, in wrapped_view
    return view_func(*args, **kwargs)
  File "/Users/aksharasadheesh/Desktop/tigerlab/venv/lib/python3.10/site-packages/rest_framework/viewsets.py", line 125, in view
    return self.dispatch(request, *args, **kwargs)
  File "/Users/aksharasadheesh/Desktop/tigerlab/venv/lib/python3.10/site-packages/rest_framework/views.py", line 509, in dispatch
    response = self.handle_exception(exc)
  File "/Users/aksharasadheesh/Desktop/tigerlab/venv/lib/python3.10/site-packages/rest_framework/views.py", line 469, in handle_exception
    self.raise_uncaught_exception(exc)
  File "/Users/aksharasadheesh/Desktop/tigerlab/venv/lib/python3.10/site-packages/rest_framework/views.py", line 480, in raise_uncaught_exception
    raise exc
  File "/Users/aksharasadheesh/Desktop/tigerlab/venv/lib/python3.10/site-packages/rest_framework/views.py", line 506, in dispatch
    response = handler(request, *args, **kwargs)
  File "/Users/aksharasadheesh/Desktop/tigerlab/api/views.py", line 64, in uploadfile
    i = i.split(", ")
AttributeError: 'list' object has no attribute 'split'
INFO:django.utils.autoreload:/Users/aksharasadheesh/Desktop/tigerlab/api/views.py changed, reloading.
DEBUG:root:Traceback (most recent call last):
  File "/Users/aksharasadheesh/Desktop/tigerlab/api/views.py", line 38, in uploadfile
    objs = [
  File "/Users/aksharasadheesh/Desktop/tigerlab/api/views.py", line 42, in <listcomp>
    team_name_1 = row["team_1 name"],
KeyError: 'team_1 name'

INFO:root:Success key fall back
ERROR:django.request:Internal Server Error: /ranks/uploadfile/
Traceback (most recent call last):
  File "/Users/aksharasadheesh/Desktop/tigerlab/api/views.py", line 38, in uploadfile
    objs = [
  File "/Users/aksharasadheesh/Desktop/tigerlab/api/views.py", line 42, in <listcomp>
    team_name_1 = row["team_1 name"],
KeyError: 'team_1 name'

During handling of the above exception, another exception occurred:

Traceback (most recent call last):
  File "/Users/aksharasadheesh/Desktop/tigerlab/venv/lib/python3.10/site-packages/django/core/handlers/exception.py", line 56, in inner
    response = get_response(request)
  File "/Users/aksharasadheesh/Desktop/tigerlab/venv/lib/python3.10/site-packages/django/core/handlers/base.py", line 197, in _get_response
    response = wrapped_callback(request, *callback_args, **callback_kwargs)
  File "/Users/aksharasadheesh/Desktop/tigerlab/venv/lib/python3.10/site-packages/django/views/decorators/csrf.py", line 55, in wrapped_view
    return view_func(*args, **kwargs)
  File "/Users/aksharasadheesh/Desktop/tigerlab/venv/lib/python3.10/site-packages/rest_framework/viewsets.py", line 125, in view
    return self.dispatch(request, *args, **kwargs)
  File "/Users/aksharasadheesh/Desktop/tigerlab/venv/lib/python3.10/site-packages/rest_framework/views.py", line 509, in dispatch
    response = self.handle_exception(exc)
  File "/Users/aksharasadheesh/Desktop/tigerlab/venv/lib/python3.10/site-packages/rest_framework/views.py", line 469, in handle_exception
    self.raise_uncaught_exception(exc)
  File "/Users/aksharasadheesh/Desktop/tigerlab/venv/lib/python3.10/site-packages/rest_framework/views.py", line 480, in raise_uncaught_exception
    raise exc
  File "/Users/aksharasadheesh/Desktop/tigerlab/venv/lib/python3.10/site-packages/rest_framework/views.py", line 506, in dispatch
    response = handler(request, *args, **kwargs)
  File "/Users/aksharasadheesh/Desktop/tigerlab/api/views.py", line 64, in uploadfile
    i = list(i.split(","))
AttributeError: 'list' object has no attribute 'split'
INFO:django.utils.autoreload:/Users/aksharasadheesh/Desktop/tigerlab/api/views.py changed, reloading.
INFO:django.utils.autoreload:/Users/aksharasadheesh/Desktop/tigerlab/api/views.py changed, reloading.
DEBUG:root:Traceback (most recent call last):
  File "/Users/aksharasadheesh/Desktop/tigerlab/api/views.py", line 38, in uploadfile
    objs = [
  File "/Users/aksharasadheesh/Desktop/tigerlab/api/views.py", line 42, in <listcomp>
    team_name_1 = row["team_1 name"],
KeyError: 'team_1 name'

INFO:root:Success key fall back
ERROR:django.request:Internal Server Error: /ranks/uploadfile/
Traceback (most recent call last):
  File "/Users/aksharasadheesh/Desktop/tigerlab/api/views.py", line 38, in uploadfile
    objs = [
  File "/Users/aksharasadheesh/Desktop/tigerlab/api/views.py", line 42, in <listcomp>
    team_name_1 = row["team_1 name"],
KeyError: 'team_1 name'

During handling of the above exception, another exception occurred:

Traceback (most recent call last):
  File "/Users/aksharasadheesh/Desktop/tigerlab/venv/lib/python3.10/site-packages/django/core/handlers/exception.py", line 56, in inner
    response = get_response(request)
  File "/Users/aksharasadheesh/Desktop/tigerlab/venv/lib/python3.10/site-packages/django/core/handlers/base.py", line 197, in _get_response
    response = wrapped_callback(request, *callback_args, **callback_kwargs)
  File "/Users/aksharasadheesh/Desktop/tigerlab/venv/lib/python3.10/site-packages/django/views/decorators/csrf.py", line 55, in wrapped_view
    return view_func(*args, **kwargs)
  File "/Users/aksharasadheesh/Desktop/tigerlab/venv/lib/python3.10/site-packages/rest_framework/viewsets.py", line 125, in view
    return self.dispatch(request, *args, **kwargs)
  File "/Users/aksharasadheesh/Desktop/tigerlab/venv/lib/python3.10/site-packages/rest_framework/views.py", line 509, in dispatch
    response = self.handle_exception(exc)
  File "/Users/aksharasadheesh/Desktop/tigerlab/venv/lib/python3.10/site-packages/rest_framework/views.py", line 469, in handle_exception
    self.raise_uncaught_exception(exc)
  File "/Users/aksharasadheesh/Desktop/tigerlab/venv/lib/python3.10/site-packages/rest_framework/views.py", line 480, in raise_uncaught_exception
    raise exc
  File "/Users/aksharasadheesh/Desktop/tigerlab/venv/lib/python3.10/site-packages/rest_framework/views.py", line 506, in dispatch
    response = handler(request, *args, **kwargs)
  File "/Users/aksharasadheesh/Desktop/tigerlab/api/views.py", line 65, in uploadfile
    d = {"team_1 name" : l[0], "team_1 score" : l[1], "team_2 name" : l[2],"team_2 score" : l[3]}
IndexError: list index out of range
INFO:django.utils.autoreload:/Users/aksharasadheesh/Desktop/tigerlab/api/views.py changed, reloading.
DEBUG:root:Traceback (most recent call last):
  File "/Users/aksharasadheesh/Desktop/tigerlab/api/views.py", line 38, in uploadfile
    objs = [
  File "/Users/aksharasadheesh/Desktop/tigerlab/api/views.py", line 42, in <listcomp>
    team_name_1 = row["team_1 name"],
KeyError: 'team_1 name'

INFO:root:Success key fall back
INFO:django.utils.autoreload:/Users/aksharasadheesh/Desktop/tigerlab/api/views.py changed, reloading.
DEBUG:root:Traceback (most recent call last):
  File "/Users/aksharasadheesh/Desktop/tigerlab/api/views.py", line 38, in uploadfile
    objs = [
  File "/Users/aksharasadheesh/Desktop/tigerlab/api/views.py", line 42, in <listcomp>
    team_name_1 = row["team_1 name"],
KeyError: 'team_1 name'

INFO:root:Success key fall back
INFO:django.utils.autoreload:/Users/aksharasadheesh/Desktop/tigerlab/api/views.py changed, reloading.
DEBUG:root:Traceback (most recent call last):
  File "/Users/aksharasadheesh/Desktop/tigerlab/api/views.py", line 38, in uploadfile
    objs = [
  File "/Users/aksharasadheesh/Desktop/tigerlab/api/views.py", line 42, in <listcomp>
    team_name_1 = row["team_1 name"],
KeyError: 'team_1 name'

INFO:root:Success key fall back
ERROR:django.request:Internal Server Error: /ranks/uploadfile/
Traceback (most recent call last):
  File "/Users/aksharasadheesh/Desktop/tigerlab/venv/lib/python3.10/site-packages/django/core/handlers/exception.py", line 56, in inner
    response = get_response(request)
  File "/Users/aksharasadheesh/Desktop/tigerlab/venv/lib/python3.10/site-packages/django/core/handlers/base.py", line 220, in _get_response
    response = response.render()
  File "/Users/aksharasadheesh/Desktop/tigerlab/venv/lib/python3.10/site-packages/django/template/response.py", line 114, in render
    self.content = self.rendered_content
  File "/Users/aksharasadheesh/Desktop/tigerlab/venv/lib/python3.10/site-packages/rest_framework/response.py", line 70, in rendered_content
    ret = renderer.render(self.data, accepted_media_type, context)
  File "/Users/aksharasadheesh/Desktop/tigerlab/venv/lib/python3.10/site-packages/rest_framework/renderers.py", line 723, in render
    context = self.get_context(data, accepted_media_type, renderer_context)
  File "/Users/aksharasadheesh/Desktop/tigerlab/venv/lib/python3.10/site-packages/rest_framework/renderers.py", line 679, in get_context
    'content': self.get_content(renderer, data, accepted_media_type, renderer_context),
  File "/Users/aksharasadheesh/Desktop/tigerlab/venv/lib/python3.10/site-packages/rest_framework/renderers.py", line 412, in get_content
    content = renderer.render(data, accepted_media_type, renderer_context)
  File "/Users/aksharasadheesh/Desktop/tigerlab/venv/lib/python3.10/site-packages/rest_framework/renderers.py", line 99, in render
    ret = json.dumps(
  File "/Users/aksharasadheesh/Desktop/tigerlab/venv/lib/python3.10/site-packages/rest_framework/utils/json.py", line 25, in dumps
    return json.dumps(*args, **kwargs)
  File "/Library/Frameworks/Python.framework/Versions/3.10/lib/python3.10/json/__init__.py", line 238, in dumps
    **kw).encode(obj)
  File "/Library/Frameworks/Python.framework/Versions/3.10/lib/python3.10/json/encoder.py", line 201, in encode
    chunks = list(chunks)
  File "/Library/Frameworks/Python.framework/Versions/3.10/lib/python3.10/json/encoder.py", line 429, in _iterencode
    yield from _iterencode_list(o, _current_indent_level)
  File "/Library/Frameworks/Python.framework/Versions/3.10/lib/python3.10/json/encoder.py", line 325, in _iterencode_list
    yield from chunks
  File "/Library/Frameworks/Python.framework/Versions/3.10/lib/python3.10/json/encoder.py", line 438, in _iterencode
    o = _default(o)
  File "/Users/aksharasadheesh/Desktop/tigerlab/venv/lib/python3.10/site-packages/rest_framework/utils/encoders.py", line 67, in default
    return super().default(obj)
  File "/Library/Frameworks/Python.framework/Versions/3.10/lib/python3.10/json/encoder.py", line 179, in default
    raise TypeError(f'Object of type {o.__class__.__name__} '
TypeError: Object of type type is not JSON serializable
INFO:django.utils.autoreload:/Users/aksharasadheesh/Desktop/tigerlab/api/views.py changed, reloading.
INFO:django.utils.autoreload:/Users/aksharasadheesh/Desktop/tigerlab/api/views.py changed, reloading.
DEBUG:root:Traceback (most recent call last):
  File "/Users/aksharasadheesh/Desktop/tigerlab/api/views.py", line 38, in uploadfile
    objs = [
  File "/Users/aksharasadheesh/Desktop/tigerlab/api/views.py", line 42, in <listcomp>
    team_name_1 = row["team_1 name"],
KeyError: 'team_1 name'

INFO:root:Success key fall back
ERROR:django.request:Internal Server Error: /ranks/uploadfile/
Traceback (most recent call last):
  File "/Users/aksharasadheesh/Desktop/tigerlab/api/views.py", line 38, in uploadfile
    objs = [
  File "/Users/aksharasadheesh/Desktop/tigerlab/api/views.py", line 42, in <listcomp>
    team_name_1 = row["team_1 name"],
KeyError: 'team_1 name'

During handling of the above exception, another exception occurred:

Traceback (most recent call last):
  File "/Users/aksharasadheesh/Desktop/tigerlab/venv/lib/python3.10/site-packages/django/core/handlers/exception.py", line 56, in inner
    response = get_response(request)
  File "/Users/aksharasadheesh/Desktop/tigerlab/venv/lib/python3.10/site-packages/django/core/handlers/base.py", line 197, in _get_response
    response = wrapped_callback(request, *callback_args, **callback_kwargs)
  File "/Users/aksharasadheesh/Desktop/tigerlab/venv/lib/python3.10/site-packages/django/views/decorators/csrf.py", line 55, in wrapped_view
    return view_func(*args, **kwargs)
  File "/Users/aksharasadheesh/Desktop/tigerlab/venv/lib/python3.10/site-packages/rest_framework/viewsets.py", line 125, in view
    return self.dispatch(request, *args, **kwargs)
  File "/Users/aksharasadheesh/Desktop/tigerlab/venv/lib/python3.10/site-packages/rest_framework/views.py", line 509, in dispatch
    response = self.handle_exception(exc)
  File "/Users/aksharasadheesh/Desktop/tigerlab/venv/lib/python3.10/site-packages/rest_framework/views.py", line 469, in handle_exception
    self.raise_uncaught_exception(exc)
  File "/Users/aksharasadheesh/Desktop/tigerlab/venv/lib/python3.10/site-packages/rest_framework/views.py", line 480, in raise_uncaught_exception
    raise exc
  File "/Users/aksharasadheesh/Desktop/tigerlab/venv/lib/python3.10/site-packages/rest_framework/views.py", line 506, in dispatch
    response = handler(request, *args, **kwargs)
  File "/Users/aksharasadheesh/Desktop/tigerlab/api/views.py", line 65, in uploadfile
    d = {"team_1 name" : l[0], "team_1 score" : l[1], "team_2 name" : l[2],"team_2 score" : l[3]}
IndexError: list index out of range
INFO:django.utils.autoreload:/Users/aksharasadheesh/Desktop/tigerlab/api/views.py changed, reloading.
DEBUG:root:Traceback (most recent call last):
  File "/Users/aksharasadheesh/Desktop/tigerlab/api/views.py", line 38, in uploadfile
    objs = [
  File "/Users/aksharasadheesh/Desktop/tigerlab/api/views.py", line 42, in <listcomp>
    team_name_1 = row["team_1 name"],
KeyError: 'team_1 name'

INFO:root:Success key fall back
INFO:django.utils.autoreload:/Users/aksharasadheesh/Desktop/tigerlab/api/views.py changed, reloading.
DEBUG:root:Traceback (most recent call last):
  File "/Users/aksharasadheesh/Desktop/tigerlab/api/views.py", line 38, in uploadfile
    objs = [
  File "/Users/aksharasadheesh/Desktop/tigerlab/api/views.py", line 42, in <listcomp>
    team_name_1 = row["team_1 name"],
KeyError: 'team_1 name'

INFO:root:Success key fall back
INFO:django.utils.autoreload:/Users/aksharasadheesh/Desktop/tigerlab/api/views.py changed, reloading.
WARNING:django.request:Method Not Allowed: /ranks/uploadfile/
DEBUG:root:Traceback (most recent call last):
  File "/Users/aksharasadheesh/Desktop/tigerlab/api/views.py", line 38, in uploadfile
    objs = [
  File "/Users/aksharasadheesh/Desktop/tigerlab/api/views.py", line 42, in <listcomp>
    team_name_1 = row["team_1 name"],
KeyError: 'team_1 name'

INFO:root:Success key fall back
ERROR:django.request:Internal Server Error: /ranks/uploadfile/
Traceback (most recent call last):
  File "/Users/aksharasadheesh/Desktop/tigerlab/api/views.py", line 38, in uploadfile
    objs = [
  File "/Users/aksharasadheesh/Desktop/tigerlab/api/views.py", line 42, in <listcomp>
    team_name_1 = row["team_1 name"],
KeyError: 'team_1 name'

During handling of the above exception, another exception occurred:

Traceback (most recent call last):
  File "/Users/aksharasadheesh/Desktop/tigerlab/venv/lib/python3.10/site-packages/django/core/handlers/exception.py", line 56, in inner
    response = get_response(request)
  File "/Users/aksharasadheesh/Desktop/tigerlab/venv/lib/python3.10/site-packages/django/core/handlers/base.py", line 197, in _get_response
    response = wrapped_callback(request, *callback_args, **callback_kwargs)
  File "/Users/aksharasadheesh/Desktop/tigerlab/venv/lib/python3.10/site-packages/django/views/decorators/csrf.py", line 55, in wrapped_view
    return view_func(*args, **kwargs)
  File "/Users/aksharasadheesh/Desktop/tigerlab/venv/lib/python3.10/site-packages/rest_framework/viewsets.py", line 125, in view
    return self.dispatch(request, *args, **kwargs)
  File "/Users/aksharasadheesh/Desktop/tigerlab/venv/lib/python3.10/site-packages/rest_framework/views.py", line 509, in dispatch
    response = self.handle_exception(exc)
  File "/Users/aksharasadheesh/Desktop/tigerlab/venv/lib/python3.10/site-packages/rest_framework/views.py", line 469, in handle_exception
    self.raise_uncaught_exception(exc)
  File "/Users/aksharasadheesh/Desktop/tigerlab/venv/lib/python3.10/site-packages/rest_framework/views.py", line 480, in raise_uncaught_exception
    raise exc
  File "/Users/aksharasadheesh/Desktop/tigerlab/venv/lib/python3.10/site-packages/rest_framework/views.py", line 506, in dispatch
    response = handler(request, *args, **kwargs)
  File "/Users/aksharasadheesh/Desktop/tigerlab/api/views.py", line 65, in uploadfile
    x = l.split(", ")
AttributeError: 'list' object has no attribute 'split'
INFO:django.utils.autoreload:/Users/aksharasadheesh/Desktop/tigerlab/api/views.py changed, reloading.
DEBUG:root:Traceback (most recent call last):
  File "/Users/aksharasadheesh/Desktop/tigerlab/api/views.py", line 38, in uploadfile
    objs = [
  File "/Users/aksharasadheesh/Desktop/tigerlab/api/views.py", line 42, in <listcomp>
    team_name_1 = row["team_1 name"],
KeyError: 'team_1 name'

INFO:root:Success key fall back
INFO:django.utils.autoreload:/Users/aksharasadheesh/Desktop/tigerlab/api/views.py changed, reloading.
DEBUG:root:Traceback (most recent call last):
  File "/Users/aksharasadheesh/Desktop/tigerlab/api/views.py", line 38, in uploadfile
    objs = [
  File "/Users/aksharasadheesh/Desktop/tigerlab/api/views.py", line 42, in <listcomp>
    team_name_1 = row["team_1 name"],
KeyError: 'team_1 name'

INFO:root:Success key fall back
INFO:root:Success no key error
DEBUG:root:Traceback (most recent call last):
  File "/Users/aksharasadheesh/Desktop/tigerlab/api/views.py", line 38, in uploadfile
    objs = [
  File "/Users/aksharasadheesh/Desktop/tigerlab/api/views.py", line 42, in <listcomp>
    team_name_1 = row["team_1 name"],
KeyError: 'team_1 name'

INFO:root:Success key fall back
ERROR:django.request:Internal Server Error: /ranks/uploadfile/
Traceback (most recent call last):
  File "/Users/aksharasadheesh/Desktop/tigerlab/api/views.py", line 38, in uploadfile
    objs = [
  File "/Users/aksharasadheesh/Desktop/tigerlab/api/views.py", line 42, in <listcomp>
    team_name_1 = row["team_1 name"],
KeyError: 'team_1 name'

During handling of the above exception, another exception occurred:

Traceback (most recent call last):
  File "/Users/aksharasadheesh/Desktop/tigerlab/venv/lib/python3.10/site-packages/django/core/handlers/exception.py", line 56, in inner
    response = get_response(request)
  File "/Users/aksharasadheesh/Desktop/tigerlab/venv/lib/python3.10/site-packages/django/core/handlers/base.py", line 197, in _get_response
    response = wrapped_callback(request, *callback_args, **callback_kwargs)
  File "/Users/aksharasadheesh/Desktop/tigerlab/venv/lib/python3.10/site-packages/django/views/decorators/csrf.py", line 55, in wrapped_view
    return view_func(*args, **kwargs)
  File "/Users/aksharasadheesh/Desktop/tigerlab/venv/lib/python3.10/site-packages/rest_framework/viewsets.py", line 125, in view
    return self.dispatch(request, *args, **kwargs)
  File "/Users/aksharasadheesh/Desktop/tigerlab/venv/lib/python3.10/site-packages/rest_framework/views.py", line 509, in dispatch
    response = self.handle_exception(exc)
  File "/Users/aksharasadheesh/Desktop/tigerlab/venv/lib/python3.10/site-packages/rest_framework/views.py", line 469, in handle_exception
    self.raise_uncaught_exception(exc)
  File "/Users/aksharasadheesh/Desktop/tigerlab/venv/lib/python3.10/site-packages/rest_framework/views.py", line 480, in raise_uncaught_exception
    raise exc
  File "/Users/aksharasadheesh/Desktop/tigerlab/venv/lib/python3.10/site-packages/rest_framework/views.py", line 506, in dispatch
    response = handler(request, *args, **kwargs)
  File "/Users/aksharasadheesh/Desktop/tigerlab/api/views.py", line 66, in uploadfile
    d = {"team_1 name" : x[0], "team_1 score" : x[1], "team_2 name" : x[2],"team_2 score" : x[3]}
IndexError: list index out of range
INFO:django.utils.autoreload:/Users/aksharasadheesh/Desktop/tigerlab/api/views.py changed, reloading.
DEBUG:root:Traceback (most recent call last):
  File "/Users/aksharasadheesh/Desktop/tigerlab/api/views.py", line 38, in uploadfile
    objs = [
  File "/Users/aksharasadheesh/Desktop/tigerlab/api/views.py", line 42, in <listcomp>
    team_name_1 = row["team_1 name"],
KeyError: 'team_1 name'

INFO:root:Success key fall back
ERROR:django.request:Internal Server Error: /ranks/uploadfile/
Traceback (most recent call last):
  File "/Users/aksharasadheesh/Desktop/tigerlab/api/views.py", line 38, in uploadfile
    objs = [
  File "/Users/aksharasadheesh/Desktop/tigerlab/api/views.py", line 42, in <listcomp>
    team_name_1 = row["team_1 name"],
KeyError: 'team_1 name'

During handling of the above exception, another exception occurred:

Traceback (most recent call last):
  File "/Users/aksharasadheesh/Desktop/tigerlab/venv/lib/python3.10/site-packages/django/core/handlers/exception.py", line 56, in inner
    response = get_response(request)
  File "/Users/aksharasadheesh/Desktop/tigerlab/venv/lib/python3.10/site-packages/django/core/handlers/base.py", line 197, in _get_response
    response = wrapped_callback(request, *callback_args, **callback_kwargs)
  File "/Users/aksharasadheesh/Desktop/tigerlab/venv/lib/python3.10/site-packages/django/views/decorators/csrf.py", line 55, in wrapped_view
    return view_func(*args, **kwargs)
  File "/Users/aksharasadheesh/Desktop/tigerlab/venv/lib/python3.10/site-packages/rest_framework/viewsets.py", line 125, in view
    return self.dispatch(request, *args, **kwargs)
  File "/Users/aksharasadheesh/Desktop/tigerlab/venv/lib/python3.10/site-packages/rest_framework/views.py", line 509, in dispatch
    response = self.handle_exception(exc)
  File "/Users/aksharasadheesh/Desktop/tigerlab/venv/lib/python3.10/site-packages/rest_framework/views.py", line 469, in handle_exception
    self.raise_uncaught_exception(exc)
  File "/Users/aksharasadheesh/Desktop/tigerlab/venv/lib/python3.10/site-packages/rest_framework/views.py", line 480, in raise_uncaught_exception
    raise exc
  File "/Users/aksharasadheesh/Desktop/tigerlab/venv/lib/python3.10/site-packages/rest_framework/views.py", line 506, in dispatch
    response = handler(request, *args, **kwargs)
  File "/Users/aksharasadheesh/Desktop/tigerlab/api/views.py", line 66, in uploadfile
    d = {headers[0] : x[0], headers[1]  : x[1], headers[2]  : x[2], headers[3] : x[3]}
IndexError: list index out of range
INFO:django.utils.autoreload:/Users/aksharasadheesh/Desktop/tigerlab/api/views.py changed, reloading.
INFO:django.utils.autoreload:/Users/aksharasadheesh/Desktop/tigerlab/api/views.py changed, reloading.
DEBUG:root:Traceback (most recent call last):
  File "/Users/aksharasadheesh/Desktop/tigerlab/api/views.py", line 38, in uploadfile
    objs = [
  File "/Users/aksharasadheesh/Desktop/tigerlab/api/views.py", line 42, in <listcomp>
    team_name_1 = row["team_1 name"],
KeyError: 'team_1 name'

INFO:root:Success key fall back
INFO:django.utils.autoreload:/Users/aksharasadheesh/Desktop/tigerlab/api/views.py changed, reloading.
DEBUG:root:Traceback (most recent call last):
  File "/Users/aksharasadheesh/Desktop/tigerlab/api/views.py", line 38, in uploadfile
    objs = [
  File "/Users/aksharasadheesh/Desktop/tigerlab/api/views.py", line 42, in <listcomp>
    team_name_1 = row["team_1 name"],
KeyError: 'team_1 name'

INFO:root:Success key fall back
ERROR:django.request:Internal Server Error: /ranks/uploadfile/
Traceback (most recent call last):
  File "/Users/aksharasadheesh/Desktop/tigerlab/api/views.py", line 38, in uploadfile
    objs = [
  File "/Users/aksharasadheesh/Desktop/tigerlab/api/views.py", line 42, in <listcomp>
    team_name_1 = row["team_1 name"],
KeyError: 'team_1 name'

During handling of the above exception, another exception occurred:

Traceback (most recent call last):
  File "/Users/aksharasadheesh/Desktop/tigerlab/venv/lib/python3.10/site-packages/django/core/handlers/exception.py", line 56, in inner
    response = get_response(request)
  File "/Users/aksharasadheesh/Desktop/tigerlab/venv/lib/python3.10/site-packages/django/core/handlers/base.py", line 197, in _get_response
    response = wrapped_callback(request, *callback_args, **callback_kwargs)
  File "/Users/aksharasadheesh/Desktop/tigerlab/venv/lib/python3.10/site-packages/django/views/decorators/csrf.py", line 55, in wrapped_view
    return view_func(*args, **kwargs)
  File "/Users/aksharasadheesh/Desktop/tigerlab/venv/lib/python3.10/site-packages/rest_framework/viewsets.py", line 125, in view
    return self.dispatch(request, *args, **kwargs)
  File "/Users/aksharasadheesh/Desktop/tigerlab/venv/lib/python3.10/site-packages/rest_framework/views.py", line 509, in dispatch
    response = self.handle_exception(exc)
  File "/Users/aksharasadheesh/Desktop/tigerlab/venv/lib/python3.10/site-packages/rest_framework/views.py", line 469, in handle_exception
    self.raise_uncaught_exception(exc)
  File "/Users/aksharasadheesh/Desktop/tigerlab/venv/lib/python3.10/site-packages/rest_framework/views.py", line 480, in raise_uncaught_exception
    raise exc
  File "/Users/aksharasadheesh/Desktop/tigerlab/venv/lib/python3.10/site-packages/rest_framework/views.py", line 506, in dispatch
    response = handler(request, *args, **kwargs)
  File "/Users/aksharasadheesh/Desktop/tigerlab/api/views.py", line 67, in uploadfile
    d = {titles[0] : x[0], titles[1]  : x[1], titles[2]  : x[2], titles[3] : x[3]}
IndexError: list index out of range
INFO:django.utils.autoreload:/Users/aksharasadheesh/Desktop/tigerlab/api/views.py changed, reloading.
DEBUG:root:Traceback (most recent call last):
  File "/Users/aksharasadheesh/Desktop/tigerlab/api/views.py", line 38, in uploadfile
    objs = [
  File "/Users/aksharasadheesh/Desktop/tigerlab/api/views.py", line 42, in <listcomp>
    team_name_1 = row["team_1 name"],
KeyError: 'team_1 name'

INFO:root:Success key fall back
ERROR:django.request:Internal Server Error: /ranks/uploadfile/
Traceback (most recent call last):
  File "/Users/aksharasadheesh/Desktop/tigerlab/api/views.py", line 38, in uploadfile
    objs = [
  File "/Users/aksharasadheesh/Desktop/tigerlab/api/views.py", line 42, in <listcomp>
    team_name_1 = row["team_1 name"],
KeyError: 'team_1 name'

During handling of the above exception, another exception occurred:

Traceback (most recent call last):
  File "/Users/aksharasadheesh/Desktop/tigerlab/venv/lib/python3.10/site-packages/django/core/handlers/exception.py", line 56, in inner
    response = get_response(request)
  File "/Users/aksharasadheesh/Desktop/tigerlab/venv/lib/python3.10/site-packages/django/core/handlers/base.py", line 197, in _get_response
    response = wrapped_callback(request, *callback_args, **callback_kwargs)
  File "/Users/aksharasadheesh/Desktop/tigerlab/venv/lib/python3.10/site-packages/django/views/decorators/csrf.py", line 55, in wrapped_view
    return view_func(*args, **kwargs)
  File "/Users/aksharasadheesh/Desktop/tigerlab/venv/lib/python3.10/site-packages/rest_framework/viewsets.py", line 125, in view
    return self.dispatch(request, *args, **kwargs)
  File "/Users/aksharasadheesh/Desktop/tigerlab/venv/lib/python3.10/site-packages/rest_framework/views.py", line 509, in dispatch
    response = self.handle_exception(exc)
  File "/Users/aksharasadheesh/Desktop/tigerlab/venv/lib/python3.10/site-packages/rest_framework/views.py", line 469, in handle_exception
    self.raise_uncaught_exception(exc)
  File "/Users/aksharasadheesh/Desktop/tigerlab/venv/lib/python3.10/site-packages/rest_framework/views.py", line 480, in raise_uncaught_exception
    raise exc
  File "/Users/aksharasadheesh/Desktop/tigerlab/venv/lib/python3.10/site-packages/rest_framework/views.py", line 506, in dispatch
    response = handler(request, *args, **kwargs)
  File "/Users/aksharasadheesh/Desktop/tigerlab/api/views.py", line 67, in uploadfile
    d = {f"{titles[0]}" : x[0], f"{titles[1]}" : x[1], f"{titles[2]}" : x[2], f"{titles[3]}" : x[3]}
IndexError: list index out of range
INFO:django.utils.autoreload:/Users/aksharasadheesh/Desktop/tigerlab/api/views.py changed, reloading.
DEBUG:root:Traceback (most recent call last):
  File "/Users/aksharasadheesh/Desktop/tigerlab/api/views.py", line 38, in uploadfile
    objs = [
  File "/Users/aksharasadheesh/Desktop/tigerlab/api/views.py", line 42, in <listcomp>
    team_name_1 = row["team_1 name"],
KeyError: 'team_1 name'

INFO:root:Success key fall back
INFO:django.utils.autoreload:/Users/aksharasadheesh/Desktop/tigerlab/api/views.py changed, reloading.
DEBUG:root:Traceback (most recent call last):
  File "/Users/aksharasadheesh/Desktop/tigerlab/api/views.py", line 38, in uploadfile
    objs = [
  File "/Users/aksharasadheesh/Desktop/tigerlab/api/views.py", line 42, in <listcomp>
    team_name_1 = row["team_1 name"],
KeyError: 'team_1 name'

INFO:root:Success key fall back
INFO:django.utils.autoreload:/Users/aksharasadheesh/Desktop/tigerlab/api/views.py changed, reloading.
DEBUG:root:Traceback (most recent call last):
  File "/Users/aksharasadheesh/Desktop/tigerlab/api/views.py", line 38, in uploadfile
    objs = [
  File "/Users/aksharasadheesh/Desktop/tigerlab/api/views.py", line 42, in <listcomp>
    team_name_1 = row["team_1 name"],
KeyError: 'team_1 name'

INFO:root:Success key fall back
INFO:root:Success no key error
DEBUG:root:Traceback (most recent call last):
  File "/Users/aksharasadheesh/Desktop/tigerlab/api/views.py", line 38, in uploadfile
    objs = [
  File "/Users/aksharasadheesh/Desktop/tigerlab/api/views.py", line 42, in <listcomp>
    team_name_1 = row["team_1 name"],
KeyError: 'team_1 name'

INFO:root:Success key fall back
ERROR:django.request:Internal Server Error: /ranks/uploadfile/
Traceback (most recent call last):
  File "/Users/aksharasadheesh/Desktop/tigerlab/api/views.py", line 38, in uploadfile
    objs = [
  File "/Users/aksharasadheesh/Desktop/tigerlab/api/views.py", line 42, in <listcomp>
    team_name_1 = row["team_1 name"],
KeyError: 'team_1 name'

During handling of the above exception, another exception occurred:

Traceback (most recent call last):
  File "/Users/aksharasadheesh/Desktop/tigerlab/venv/lib/python3.10/site-packages/django/core/handlers/exception.py", line 56, in inner
    response = get_response(request)
  File "/Users/aksharasadheesh/Desktop/tigerlab/venv/lib/python3.10/site-packages/django/core/handlers/base.py", line 197, in _get_response
    response = wrapped_callback(request, *callback_args, **callback_kwargs)
  File "/Users/aksharasadheesh/Desktop/tigerlab/venv/lib/python3.10/site-packages/django/views/decorators/csrf.py", line 55, in wrapped_view
    return view_func(*args, **kwargs)
  File "/Users/aksharasadheesh/Desktop/tigerlab/venv/lib/python3.10/site-packages/rest_framework/viewsets.py", line 125, in view
    return self.dispatch(request, *args, **kwargs)
  File "/Users/aksharasadheesh/Desktop/tigerlab/venv/lib/python3.10/site-packages/rest_framework/views.py", line 509, in dispatch
    response = self.handle_exception(exc)
  File "/Users/aksharasadheesh/Desktop/tigerlab/venv/lib/python3.10/site-packages/rest_framework/views.py", line 469, in handle_exception
    self.raise_uncaught_exception(exc)
  File "/Users/aksharasadheesh/Desktop/tigerlab/venv/lib/python3.10/site-packages/rest_framework/views.py", line 480, in raise_uncaught_exception
    raise exc
  File "/Users/aksharasadheesh/Desktop/tigerlab/venv/lib/python3.10/site-packages/rest_framework/views.py", line 506, in dispatch
    response = handler(request, *args, **kwargs)
  File "/Users/aksharasadheesh/Desktop/tigerlab/api/views.py", line 68, in uploadfile
    d = {titles[0] : x[0], titles[1]  : x[1], titles[2]  : x[2], titles[3] : x[3]}
IndexError: list index out of range
INFO:django.utils.autoreload:/Users/aksharasadheesh/Desktop/tigerlab/api/views.py changed, reloading.
INFO:root:Success no key error
DEBUG:root:Traceback (most recent call last):
  File "/Users/aksharasadheesh/Desktop/tigerlab/api/views.py", line 38, in uploadfile
    objs = [
  File "/Users/aksharasadheesh/Desktop/tigerlab/api/views.py", line 42, in <listcomp>
    team_name_1 = row["team_1 name"],
KeyError: 'team_1 name'

INFO:root:Success key fall back
DEBUG:root:Traceback (most recent call last):
  File "/Users/aksharasadheesh/Desktop/tigerlab/api/views.py", line 38, in uploadfile
    objs = [
  File "/Users/aksharasadheesh/Desktop/tigerlab/api/views.py", line 42, in <listcomp>
    team_name_1 = row["team_1 name"],
KeyError: 'team_1 name'

INFO:root:Success key fall back
DEBUG:root:Traceback (most recent call last):
  File "/Users/aksharasadheesh/Desktop/tigerlab/api/views.py", line 38, in uploadfile
    objs = [
  File "/Users/aksharasadheesh/Desktop/tigerlab/api/views.py", line 42, in <listcomp>
    team_name_1 = row["team_1 name"],
KeyError: 'team_1 name'

During handling of the above exception, another exception occurred:

Traceback (most recent call last):
  File "/Users/aksharasadheesh/Desktop/tigerlab/api/views.py", line 69, in uploadfile
    d = {titles[0] : x[0], titles[1]  : x[1], titles[2]  : x[2], titles[3] : x[3]}
IndexError: list index out of range

INFO:django.utils.autoreload:/Users/aksharasadheesh/Desktop/tigerlab/api/views.py changed, reloading.
INFO:django.utils.autoreload:/Users/aksharasadheesh/Desktop/tigerlab/api/views.py changed, reloading.
INFO:root:Success no key error
DEBUG:root:Traceback (most recent call last):
  File "/Users/aksharasadheesh/Desktop/tigerlab/api/views.py", line 38, in uploadfile
    objs = [
  File "/Users/aksharasadheesh/Desktop/tigerlab/api/views.py", line 42, in <listcomp>
    team_name_1 = row["team_1 name"],
KeyError: 'team_1 name'

INFO:root:Success key fall back
DEBUG:root:Traceback (most recent call last):
  File "/Users/aksharasadheesh/Desktop/tigerlab/api/views.py", line 38, in uploadfile
    objs = [
  File "/Users/aksharasadheesh/Desktop/tigerlab/api/views.py", line 42, in <listcomp>
    team_name_1 = row["team_1 name"],
KeyError: 'team_1 name'

INFO:root:Success key fall back
DEBUG:root:Traceback (most recent call last):
  File "/Users/aksharasadheesh/Desktop/tigerlab/api/views.py", line 38, in uploadfile
    objs = [
  File "/Users/aksharasadheesh/Desktop/tigerlab/api/views.py", line 42, in <listcomp>
    team_name_1 = row["team_1 name"],
KeyError: 'team_1 name'

During handling of the above exception, another exception occurred:

Traceback (most recent call last):
  File "/Users/aksharasadheesh/Desktop/tigerlab/api/views.py", line 69, in uploadfile
    d = {titles[0] : x[0], titles[1]  : x[1], titles[2]  : x[2], titles[3] : x[3]}
IndexError: list index out of range

DEBUG:root:Traceback (most recent call last):
  File "/Users/aksharasadheesh/Desktop/tigerlab/api/views.py", line 38, in uploadfile
    objs = [
  File "/Users/aksharasadheesh/Desktop/tigerlab/api/views.py", line 42, in <listcomp>
    team_name_1 = row["team_1 name"],
KeyError: 'team_1 name'

INFO:root:Success key fall back
DEBUG:root:Traceback (most recent call last):
  File "/Users/aksharasadheesh/Desktop/tigerlab/api/views.py", line 38, in uploadfile
    objs = [
  File "/Users/aksharasadheesh/Desktop/tigerlab/api/views.py", line 42, in <listcomp>
    team_name_1 = row["team_1 name"],
KeyError: 'team_1 name'

During handling of the above exception, another exception occurred:

Traceback (most recent call last):
  File "/Users/aksharasadheesh/Desktop/tigerlab/api/views.py", line 69, in uploadfile
    d = {titles[0] : x[0], titles[1]  : x[1], titles[2]  : x[2], titles[3] : x[3]}
IndexError: list index out of range

INFO:django.utils.autoreload:/Users/aksharasadheesh/Desktop/tigerlab/api/views.py changed, reloading.
INFO:root:Success no key error, Time : 2023-02-16 04:04:58.020964+00:00
DEBUG:root:Traceback (most recent call last):
  File "/Users/aksharasadheesh/Desktop/tigerlab/api/views.py", line 38, in uploadfile
    objs = [
  File "/Users/aksharasadheesh/Desktop/tigerlab/api/views.py", line 42, in <listcomp>
    team_name_1 = row["team_1 name"],
KeyError: 'team_1 name'

INFO:root:Success key fall back, Time : 2023-02-16 04:05:19.857651+00:00
INFO:django.utils.autoreload:/Users/aksharasadheesh/Desktop/tigerlab/api/views.py changed, reloading.
INFO:root:Success key fall back, Time : 2023-02-16 04:05:48.460371+00:00
INFO:root:Success no key error, Time : 2023-02-16 04:06:01.353786+00:00
INFO:root:Success key fall back, Time : 2023-02-16 04:06:11.873536+00:00
DEBUG:root:Invalid file, Time : 2023-02-16 04:06:11.881683+00:00
DEBUG:root:Traceback (most recent call last):
  File "/Users/aksharasadheesh/Desktop/tigerlab/api/views.py", line 38, in uploadfile
    objs = [
  File "/Users/aksharasadheesh/Desktop/tigerlab/api/views.py", line 42, in <listcomp>
    team_name_1 = row["team_1 name"],
KeyError: 'team_1 name'

During handling of the above exception, another exception occurred:

Traceback (most recent call last):
  File "/Users/aksharasadheesh/Desktop/tigerlab/api/views.py", line 68, in uploadfile
    d = {titles[0] : x[0], titles[1]  : x[1], titles[2]  : x[2], titles[3] : x[3]}
IndexError: list index out of range

INFO:django.utils.autoreload:/Users/aksharasadheesh/Desktop/tigerlab/api/views.py changed, reloading.
INFO:django.utils.autoreload:/Users/aksharasadheesh/Desktop/tigerlab/api/views.py changed, reloading.
INFO:root:Success no key error, Time : 2023-02-16 04:08:09.545103+00:00
INFO:root:Success key fall back, Time : 2023-02-16 04:08:15.545368+00:00
INFO:root:Success key fall back, Time : 2023-02-16 04:08:26.495731+00:00
DEBUG:root:Invalid file, Time : 2023-02-16 04:08:26.497803+00:00
DEBUG:root:Traceback (most recent call last):
  File "/Users/aksharasadheesh/Desktop/tigerlab/api/views.py", line 38, in uploadfile
    objs = [
  File "/Users/aksharasadheesh/Desktop/tigerlab/api/views.py", line 42, in <listcomp>
    team_name_1 = row["team_1 name"],
KeyError: 'team_1 name'

During handling of the above exception, another exception occurred:

Traceback (most recent call last):
  File "/Users/aksharasadheesh/Desktop/tigerlab/api/views.py", line 68, in uploadfile
    d = {titles[0] : x[0], titles[1]  : x[1], titles[2]  : x[2], titles[3] : x[3]}
IndexError: list index out of range

INFO:root:Success key fall back, Time : 2023-02-16 04:08:33.391904+00:00
INFO:django.utils.autoreload:/Users/aksharasadheesh/Desktop/tigerlab/api/views.py changed, reloading.
WARNING:django.request:Not Found: /accounts/profile
WARNING:django.request:Not Found: /accounts/profile
INFO:django.utils.autoreload:/Users/aksharasadheesh/Desktop/tigerlab/coreapp/views.py changed, reloading.
INFO:django.utils.autoreload:/Users/aksharasadheesh/Desktop/tigerlab/coreapp/views.py changed, reloading.
INFO:django.utils.autoreload:/Users/aksharasadheesh/Desktop/tigerlab/coreapp/views.py changed, reloading.
INFO:django.utils.autoreload:/Users/aksharasadheesh/Desktop/tigerlab/coreapp/views.py changed, reloading.
INFO:django.utils.autoreload:/Users/aksharasadheesh/Desktop/tigerlab/coreapp/views.py changed, reloading.
INFO:django.utils.autoreload:/Users/aksharasadheesh/Desktop/tigerlab/coreapp/views.py changed, reloading.
INFO:django.utils.autoreload:/Users/aksharasadheesh/Desktop/tigerlab/coreapp/views.py changed, reloading.
INFO:django.utils.autoreload:/Users/aksharasadheesh/Desktop/tigerlab/coreapp/views.py changed, reloading.
